{"timestamp": "2023-09-08 13:04:24", "level": "INFO", "module": "test", "function": "<module>", "line": 38, "message": "ddqc-- execution started", "process": "ddqc"}
{"timestamp": "2023-09-08 13:09:05", "level": "INFO", "module": "test", "function": "<module>", "line": 38, "message": "ddqc-- execution started", "process": "ddqc"}
{"timestamp": "2023-09-08 13:09:27", "level": "ERROR", "module": "test", "function": "<module>", "line": 52, "message": "Traceback (most recent call last):\n  File \"c:\\Users\\mjeevaba\\Documents\\Python\\DDQC\\DDQC 2.0\\Code\\DDQC Rule Engine\\test.py\", line 50, in <module>\n    dict_transaction = process(config, dict_transaction)\n                       ^^^^^^^^^^^^^^^^^^^^^^^^^^^^^^^^^\n  File \"c:\\Users\\mjeevaba\\Documents\\Python\\DDQC\\DDQC 2.0\\Code\\DDQC Rule Engine\\Project\\z_process.py\", line 18, in process\n    dict_transaction = call_data_filter.ph2_data_filter(config, dict_transaction)\n                       ^^^^^^^^^^^^^^^^^^^^^^^^^^^^^^^^^^^^^^^^^^^^^^^^^^^^^^^^^^\n  File \"c:\\Users\\mjeevaba\\Documents\\Python\\DDQC\\DDQC 2.0\\Code\\DDQC Rule Engine\\Project\\call_data_filter.py\", line 68, in ph2_data_filter\n    'DG Retail - Scoring':ddqc2.req6_dg_retail_scroing(Refs.ph2_ref4_list, Refs.ph2_dg_retail_client_id_starts),\n                          ^^^^^^^^^^^^^^^^^^^^^^^^^^^^^^^^^^^^^^^^^^^^^^^^^^^^^^^^^^^^^^^^^^^^^^^^^^^^^^^^^^^^^\n  File \"c:\\Users\\mjeevaba\\Documents\\Python\\DDQC\\DDQC 2.0\\Code\\DDQC Rule Engine\\Project\\data_filter_ph2.py\", line 204, in req6_dg_retail_scroing\n    df_gen_rule1 = df_gen_rule1[df_gen_rule1['client id'].str.startswith(client_id)]\n                                ^^^^^^^^^^^^^^^^^^^^^^^^^^^^^\n  File \"C:\\Users\\mjeevaba\\AppData\\Local\\Programs\\Python\\Python311\\Lib\\site-packages\\pandas\\core\\generic.py\", line 5989, in __getattr__\n    return object.__getattribute__(self, name)\n           ^^^^^^^^^^^^^^^^^^^^^^^^^^^^^^^^^^^\n  File \"C:\\Users\\mjeevaba\\AppData\\Local\\Programs\\Python\\Python311\\Lib\\site-packages\\pandas\\core\\accessor.py\", line 224, in __get__\n    accessor_obj = self._accessor(obj)\n                   ^^^^^^^^^^^^^^^^^^^\n  File \"C:\\Users\\mjeevaba\\AppData\\Local\\Programs\\Python\\Python311\\Lib\\site-packages\\pandas\\core\\strings\\accessor.py\", line 181, in __init__\n    self._inferred_dtype = self._validate(data)\n                           ^^^^^^^^^^^^^^^^^^^^\n  File \"C:\\Users\\mjeevaba\\AppData\\Local\\Programs\\Python\\Python311\\Lib\\site-packages\\pandas\\core\\strings\\accessor.py\", line 235, in _validate\n    raise AttributeError(\"Can only use .str accessor with string values!\")\nAttributeError: Can only use .str accessor with string values!\n", "process": "ddqc"}
{"timestamp": "2023-09-08 13:09:47", "level": "INFO", "module": "test", "function": "<module>", "line": 38, "message": "ddqc-- execution started", "process": "ddqc"}
{"timestamp": "2023-09-08 13:11:13", "level": "ERROR", "module": "test", "function": "<module>", "line": 52, "message": "Traceback (most recent call last):\n  File \"c:\\Users\\mjeevaba\\Documents\\Python\\DDQC\\DDQC 2.0\\Code\\DDQC Rule Engine\\test.py\", line 50, in <module>\n    dict_transaction = process(config, dict_transaction)\n                       ^^^^^^^^^^^^^^^^^^^^^^^^^^^^^^^^^\n  File \"c:\\Users\\mjeevaba\\Documents\\Python\\DDQC\\DDQC 2.0\\Code\\DDQC Rule Engine\\Project\\z_process.py\", line 18, in process\n    dict_transaction = call_data_filter.ph2_data_filter(config, dict_transaction)\n                       ^^^^^^^^^^^^^^^^^^^^^^^^^^^^^^^^^^^^^^^^^^^^^^^^^^^^^^^^^^\n  File \"c:\\Users\\mjeevaba\\Documents\\Python\\DDQC\\DDQC 2.0\\Code\\DDQC Rule Engine\\Project\\call_data_filter.py\", line 68, in ph2_data_filter\n    'DG Retail - Scoring':ddqc2.req6_dg_retail_scroing(Refs.ph2_ref4_list, Refs.ph2_dg_retail_client_id_starts),\n                          ^^^^^^^^^^^^^^^^^^^^^^^^^^^^^^^^^^^^^^^^^^^^^^^^^^^^^^^^^^^^^^^^^^^^^^^^^^^^^^^^^^^^^\n  File \"c:\\Users\\mjeevaba\\Documents\\Python\\DDQC\\DDQC 2.0\\Code\\DDQC Rule Engine\\Project\\data_filter_ph2.py\", line 204, in req6_dg_retail_scroing\n    df_gen_rule1 = df_gen_rule1[df_gen_rule1['client id'].str.startswith(client_id)]\n                                ^^^^^^^^^^^^^^^^^^^^^^^^^^^^^\n  File \"C:\\Users\\mjeevaba\\AppData\\Local\\Programs\\Python\\Python311\\Lib\\site-packages\\pandas\\core\\generic.py\", line 5989, in __getattr__\n    return object.__getattribute__(self, name)\n           ^^^^^^^^^^^^^^^^^^^^^^^^^^^^^^^^^^^\n  File \"C:\\Users\\mjeevaba\\AppData\\Local\\Programs\\Python\\Python311\\Lib\\site-packages\\pandas\\core\\accessor.py\", line 224, in __get__\n    accessor_obj = self._accessor(obj)\n                   ^^^^^^^^^^^^^^^^^^^\n  File \"C:\\Users\\mjeevaba\\AppData\\Local\\Programs\\Python\\Python311\\Lib\\site-packages\\pandas\\core\\strings\\accessor.py\", line 181, in __init__\n    self._inferred_dtype = self._validate(data)\n                           ^^^^^^^^^^^^^^^^^^^^\n  File \"C:\\Users\\mjeevaba\\AppData\\Local\\Programs\\Python\\Python311\\Lib\\site-packages\\pandas\\core\\strings\\accessor.py\", line 235, in _validate\n    raise AttributeError(\"Can only use .str accessor with string values!\")\nAttributeError: Can only use .str accessor with string values!\n", "process": "ddqc"}
{"timestamp": "2023-09-08 13:11:38", "level": "INFO", "module": "test", "function": "<module>", "line": 38, "message": "ddqc-- execution started", "process": "ddqc"}
{"timestamp": "2023-09-08 13:12:36", "level": "INFO", "module": "test", "function": "<module>", "line": 38, "message": "ddqc-- execution started", "process": "ddqc"}
{"timestamp": "2023-09-08 13:14:18", "level": "INFO", "module": "test", "function": "<module>", "line": 38, "message": "ddqc-- execution started", "process": "ddqc"}
{"timestamp": "2023-09-08 13:15:20", "level": "INFO", "module": "test", "function": "<module>", "line": 38, "message": "ddqc-- execution started", "process": "ddqc"}
{"timestamp": "2023-09-08 13:18:42", "level": "INFO", "module": "test", "function": "<module>", "line": 38, "message": "ddqc-- execution started", "process": "ddqc"}
{"timestamp": "2023-09-08 13:19:11", "level": "ERROR", "module": "test", "function": "<module>", "line": 52, "message": "Traceback (most recent call last):\n  File \"c:\\Users\\mjeevaba\\Documents\\Python\\DDQC\\DDQC 2.0\\Code\\DDQC Rule Engine\\test.py\", line 50, in <module>\n    dict_transaction = process(config, dict_transaction)\n                       ^^^^^^^^^^^^^^^^^^^^^^^^^^^^^^^^^\n  File \"c:\\Users\\mjeevaba\\Documents\\Python\\DDQC\\DDQC 2.0\\Code\\DDQC Rule Engine\\Project\\z_process.py\", line 18, in process\n    dict_transaction = call_data_filter.ph2_data_filter(config, dict_transaction)\n                       ^^^^^^^^^^^^^^^^^^^^^^^^^^^^^^^^^^^^^^^^^^^^^^^^^^^^^^^^^^\n  File \"c:\\Users\\mjeevaba\\Documents\\Python\\DDQC\\DDQC 2.0\\Code\\DDQC Rule Engine\\Project\\call_data_filter.py\", line 69, in ph2_data_filter\n    'DG Retail - Hawaii':ddqc2.req7_dg_retail_hawaii(Refs.ph2_ref5_list_felony, Refs.ph2_ref5_list_misd, Refs.ph2_dg_retail_client_id_starts),\n                         ^^^^^^^^^^^^^^^^^^^^^^^^^^^^^^^^^^^^^^^^^^^^^^^^^^^^^^^^^^^^^^^^^^^^^^^^^^^^^^^^^^^^^^^^^^^^^^^^^^^^^^^^^^^^^^^^^^^^\n  File \"c:\\Users\\mjeevaba\\Documents\\Python\\DDQC\\DDQC 2.0\\Code\\DDQC Rule Engine\\Project\\data_filter_ph2.py\", line 266, in req7_dg_retail_hawaii\n    df_gen_rule1 = df_gen_rule1[df_gen_rule1[\"client id\"].str.startswith(client_id)]\n                                ^^^^^^^^^^^^^^^^^^^^^^^^^^^^^\n  File \"C:\\Users\\mjeevaba\\AppData\\Local\\Programs\\Python\\Python311\\Lib\\site-packages\\pandas\\core\\generic.py\", line 5989, in __getattr__\n    return object.__getattribute__(self, name)\n           ^^^^^^^^^^^^^^^^^^^^^^^^^^^^^^^^^^^\n  File \"C:\\Users\\mjeevaba\\AppData\\Local\\Programs\\Python\\Python311\\Lib\\site-packages\\pandas\\core\\accessor.py\", line 224, in __get__\n    accessor_obj = self._accessor(obj)\n                   ^^^^^^^^^^^^^^^^^^^\n  File \"C:\\Users\\mjeevaba\\AppData\\Local\\Programs\\Python\\Python311\\Lib\\site-packages\\pandas\\core\\strings\\accessor.py\", line 181, in __init__\n    self._inferred_dtype = self._validate(data)\n                           ^^^^^^^^^^^^^^^^^^^^\n  File \"C:\\Users\\mjeevaba\\AppData\\Local\\Programs\\Python\\Python311\\Lib\\site-packages\\pandas\\core\\strings\\accessor.py\", line 235, in _validate\n    raise AttributeError(\"Can only use .str accessor with string values!\")\nAttributeError: Can only use .str accessor with string values!\n", "process": "ddqc"}
{"timestamp": "2023-09-08 13:22:22", "level": "INFO", "module": "test", "function": "<module>", "line": 38, "message": "ddqc-- execution started", "process": "ddqc"}
{"timestamp": "2023-09-08 13:54:26", "level": "INFO", "module": "test", "function": "<module>", "line": 38, "message": "ddqc-- execution started", "process": "ddqc"}
{"timestamp": "2023-09-08 13:56:22", "level": "INFO", "module": "test", "function": "<module>", "line": 38, "message": "ddqc-- execution started", "process": "ddqc"}
{"timestamp": "2023-09-08 13:56:44", "level": "ERROR", "module": "test", "function": "<module>", "line": 52, "message": "Traceback (most recent call last):\n  File \"C:\\Users\\mjeevaba\\AppData\\Local\\Programs\\Python\\Python311\\Lib\\site-packages\\mysql\\connector\\connection_cext.py\", line 611, in cmd_query\n    self._cmysql.query(\n_mysql_connector.MySQLInterfaceError: You have an error in your SQL syntax; check the manual that corresponds to your MySQL server version for the right syntax to use near 'S','261637522','','STANDARD - PO','SCOTT,ADONIS QUINN','SCOTT, ADONIS QUINN','Ve' at line 1\n\nThe above exception was the direct cause of the following exception:\n\nTraceback (most recent call last):\n  File \"c:\\Users\\mjeevaba\\Documents\\Python\\DDQC\\DDQC 2.0\\Code\\DDQC Rule Engine\\test.py\", line 50, in <module>\n    dict_transaction = process(config, dict_transaction)\n                       ^^^^^^^^^^^^^^^^^^^^^^^^^^^^^^^^^\n  File \"c:\\Users\\mjeevaba\\Documents\\Python\\DDQC\\DDQC 2.0\\Code\\DDQC Rule Engine\\Project\\z_process.py\", line 16, in process\n    insert_to_db.insert_primary_db(config, dict_transaction)\n  File \"c:\\Users\\mjeevaba\\Documents\\Python\\DDQC\\DDQC 2.0\\Code\\DDQC Rule Engine\\Project\\insert_to_db.py\", line 108, in insert_primary_db\n    cursor.execute(query)\n  File \"C:\\Users\\mjeevaba\\AppData\\Local\\Programs\\Python\\Python311\\Lib\\site-packages\\mysql\\connector\\cursor_cext.py\", line 330, in execute\n    result = self._cnx.cmd_query(\n             ^^^^^^^^^^^^^^^^^^^^\n  File \"C:\\Users\\mjeevaba\\AppData\\Local\\Programs\\Python\\Python311\\Lib\\site-packages\\mysql\\connector\\connection_cext.py\", line 619, in cmd_query\n    raise get_mysql_exception(\nmysql.connector.errors.ProgrammingError: 1064 (42000): You have an error in your SQL syntax; check the manual that corresponds to your MySQL server version for the right syntax to use near 'S','261637522','','STANDARD - PO','SCOTT,ADONIS QUINN','SCOTT, ADONIS QUINN','Ve' at line 1\n", "process": "ddqc"}
{"timestamp": "2023-09-08 14:01:03", "level": "INFO", "module": "test", "function": "<module>", "line": 38, "message": "ddqc-- execution started", "process": "ddqc"}
{"timestamp": "2023-09-08 14:01:25", "level": "ERROR", "module": "test", "function": "<module>", "line": 52, "message": "Traceback (most recent call last):\n  File \"C:\\Users\\mjeevaba\\AppData\\Local\\Programs\\Python\\Python311\\Lib\\site-packages\\mysql\\connector\\connection_cext.py\", line 611, in cmd_query\n    self._cmysql.query(\n_mysql_connector.MySQLInterfaceError: You have an error in your SQL syntax; check the manual that corresponds to your MySQL server version for the right syntax to use near 'S','261637522','','STANDARD - PO','SCOTT,ADONIS QUINN','SCOTT, ADONIS QUINN','Ve' at line 1\n\nThe above exception was the direct cause of the following exception:\n\nTraceback (most recent call last):\n  File \"c:\\Users\\mjeevaba\\Documents\\Python\\DDQC\\DDQC 2.0\\Code\\DDQC Rule Engine\\test.py\", line 50, in <module>\n    dict_transaction = process(config, dict_transaction)\n                       ^^^^^^^^^^^^^^^^^^^^^^^^^^^^^^^^^\n  File \"c:\\Users\\mjeevaba\\Documents\\Python\\DDQC\\DDQC 2.0\\Code\\DDQC Rule Engine\\Project\\z_process.py\", line 16, in process\n    insert_to_db.insert_primary_db(config, dict_transaction)\n  File \"c:\\Users\\mjeevaba\\Documents\\Python\\DDQC\\DDQC 2.0\\Code\\DDQC Rule Engine\\Project\\insert_to_db.py\", line 108, in insert_primary_db\n    cursor.execute(query)\n  File \"C:\\Users\\mjeevaba\\AppData\\Local\\Programs\\Python\\Python311\\Lib\\site-packages\\mysql\\connector\\cursor_cext.py\", line 330, in execute\n    result = self._cnx.cmd_query(\n             ^^^^^^^^^^^^^^^^^^^^\n  File \"C:\\Users\\mjeevaba\\AppData\\Local\\Programs\\Python\\Python311\\Lib\\site-packages\\mysql\\connector\\connection_cext.py\", line 619, in cmd_query\n    raise get_mysql_exception(\nmysql.connector.errors.ProgrammingError: 1064 (42000): You have an error in your SQL syntax; check the manual that corresponds to your MySQL server version for the right syntax to use near 'S','261637522','','STANDARD - PO','SCOTT,ADONIS QUINN','SCOTT, ADONIS QUINN','Ve' at line 1\n", "process": "ddqc"}
{"timestamp": "2023-09-08 14:01:40", "level": "INFO", "module": "test", "function": "<module>", "line": 38, "message": "ddqc-- execution started", "process": "ddqc"}
{"timestamp": "2023-09-08 14:02:04", "level": "ERROR", "module": "test", "function": "<module>", "line": 52, "message": "Traceback (most recent call last):\n  File \"C:\\Users\\mjeevaba\\AppData\\Local\\Programs\\Python\\Python311\\Lib\\site-packages\\mysql\\connector\\connection_cext.py\", line 611, in cmd_query\n    self._cmysql.query(\n_mysql_connector.MySQLInterfaceError: You have an error in your SQL syntax; check the manual that corresponds to your MySQL server version for the right syntax to use near 'S','261637522','','STANDARD - PO','SCOTT,ADONIS QUINN','SCOTT, ADONIS QUINN','Ve' at line 1\n\nThe above exception was the direct cause of the following exception:\n\nTraceback (most recent call last):\n  File \"c:\\Users\\mjeevaba\\Documents\\Python\\DDQC\\DDQC 2.0\\Code\\DDQC Rule Engine\\test.py\", line 50, in <module>\n    dict_transaction = process(config, dict_transaction)\n                       ^^^^^^^^^^^^^^^^^^^^^^^^^^^^^^^^^\n  File \"c:\\Users\\mjeevaba\\Documents\\Python\\DDQC\\DDQC 2.0\\Code\\DDQC Rule Engine\\Project\\z_process.py\", line 16, in process\n    insert_to_db.insert_primary_db(config, dict_transaction)\n  File \"c:\\Users\\mjeevaba\\Documents\\Python\\DDQC\\DDQC 2.0\\Code\\DDQC Rule Engine\\Project\\insert_to_db.py\", line 108, in insert_primary_db\n    cursor.execute(query)\n  File \"C:\\Users\\mjeevaba\\AppData\\Local\\Programs\\Python\\Python311\\Lib\\site-packages\\mysql\\connector\\cursor_cext.py\", line 330, in execute\n    result = self._cnx.cmd_query(\n             ^^^^^^^^^^^^^^^^^^^^\n  File \"C:\\Users\\mjeevaba\\AppData\\Local\\Programs\\Python\\Python311\\Lib\\site-packages\\mysql\\connector\\connection_cext.py\", line 619, in cmd_query\n    raise get_mysql_exception(\nmysql.connector.errors.ProgrammingError: 1064 (42000): You have an error in your SQL syntax; check the manual that corresponds to your MySQL server version for the right syntax to use near 'S','261637522','','STANDARD - PO','SCOTT,ADONIS QUINN','SCOTT, ADONIS QUINN','Ve' at line 1\n", "process": "ddqc"}
{"timestamp": "2023-09-08 14:03:19", "level": "INFO", "module": "test", "function": "<module>", "line": 38, "message": "ddqc-- execution started", "process": "ddqc"}
{"timestamp": "2023-09-08 14:07:29", "level": "ERROR", "module": "test", "function": "<module>", "line": 52, "message": "Traceback (most recent call last):\n  File \"C:\\Users\\mjeevaba\\AppData\\Local\\Programs\\Python\\Python311\\Lib\\site-packages\\mysql\\connector\\connection_cext.py\", line 611, in cmd_query\n    self._cmysql.query(\n_mysql_connector.MySQLInterfaceError: You have an error in your SQL syntax; check the manual that corresponds to your MySQL server version for the right syntax to use near 'S','261637522','','STANDARD - PO','SCOTT,ADONIS QUINN','SCOTT, ADONIS QUINN','Ve' at line 1\n\nThe above exception was the direct cause of the following exception:\n\nTraceback (most recent call last):\n  File \"c:\\Users\\mjeevaba\\Documents\\Python\\DDQC\\DDQC 2.0\\Code\\DDQC Rule Engine\\test.py\", line 50, in <module>\n    dict_transaction = process(config, dict_transaction)\n                       ^^^^^^^^^^^^^^^^^^^^^^^^^^^^^^^^^\n  File \"c:\\Users\\mjeevaba\\Documents\\Python\\DDQC\\DDQC 2.0\\Code\\DDQC Rule Engine\\Project\\z_process.py\", line 16, in process\n    insert_to_db.insert_primary_db(config, dict_transaction)\n  File \"c:\\Users\\mjeevaba\\Documents\\Python\\DDQC\\DDQC 2.0\\Code\\DDQC Rule Engine\\Project\\insert_to_db.py\", line 108, in insert_primary_db\n    cursor.execute(query)\n  File \"C:\\Users\\mjeevaba\\AppData\\Local\\Programs\\Python\\Python311\\Lib\\site-packages\\mysql\\connector\\cursor_cext.py\", line 330, in execute\n    result = self._cnx.cmd_query(\n             ^^^^^^^^^^^^^^^^^^^^\n  File \"C:\\Users\\mjeevaba\\AppData\\Local\\Programs\\Python\\Python311\\Lib\\site-packages\\mysql\\connector\\connection_cext.py\", line 619, in cmd_query\n    raise get_mysql_exception(\nmysql.connector.errors.ProgrammingError: 1064 (42000): You have an error in your SQL syntax; check the manual that corresponds to your MySQL server version for the right syntax to use near 'S','261637522','','STANDARD - PO','SCOTT,ADONIS QUINN','SCOTT, ADONIS QUINN','Ve' at line 1\n", "process": "ddqc"}
{"timestamp": "2023-09-08 14:08:49", "level": "INFO", "module": "test", "function": "<module>", "line": 38, "message": "ddqc-- execution started", "process": "ddqc"}
{"timestamp": "2023-09-08 14:09:24", "level": "INFO", "module": "test", "function": "<module>", "line": 38, "message": "ddqc-- execution started", "process": "ddqc"}
{"timestamp": "2023-09-08 14:12:56", "level": "INFO", "module": "test", "function": "<module>", "line": 38, "message": "ddqc-- execution started", "process": "ddqc"}
{"timestamp": "2023-09-08 14:14:58", "level": "ERROR", "module": "test", "function": "<module>", "line": 52, "message": "Traceback (most recent call last):\n  File \"C:\\Users\\mjeevaba\\AppData\\Local\\Programs\\Python\\Python311\\Lib\\site-packages\\mysql\\connector\\connection_cext.py\", line 611, in cmd_query\n    self._cmysql.query(\n_mysql_connector.MySQLInterfaceError: Unknown column 'FkGuid' in 'field list'\n\nThe above exception was the direct cause of the following exception:\n\nTraceback (most recent call last):\n  File \"c:\\Users\\mjeevaba\\Documents\\Python\\DDQC\\DDQC 2.0\\Code\\DDQC Rule Engine\\test.py\", line 50, in <module>\n    dict_transaction = process(config, dict_transaction)\n                       ^^^^^^^^^^^^^^^^^^^^^^^^^^^^^^^^^\n  File \"c:\\Users\\mjeevaba\\Documents\\Python\\DDQC\\DDQC 2.0\\Code\\DDQC Rule Engine\\Project\\z_process.py\", line 18, in process\n    dict_transaction = call_data_filter.ph2_data_filter(config, dict_transaction)\n                       ^^^^^^^^^^^^^^^^^^^^^^^^^^^^^^^^^^^^^^^^^^^^^^^^^^^^^^^^^^\n  File \"c:\\Users\\mjeevaba\\Documents\\Python\\DDQC\\DDQC 2.0\\Code\\DDQC Rule Engine\\Project\\call_data_filter.py\", line 148, in ph2_data_filter\n    insert_foriegn_db(config, df)\n  File \"c:\\Users\\mjeevaba\\Documents\\Python\\DDQC\\DDQC 2.0\\Code\\DDQC Rule Engine\\Project\\insert_to_db.py\", line 172, in insert_foriegn_db\n    cursor.execute(query)\n  File \"C:\\Users\\mjeevaba\\AppData\\Local\\Programs\\Python\\Python311\\Lib\\site-packages\\mysql\\connector\\cursor_cext.py\", line 330, in execute\n    result = self._cnx.cmd_query(\n             ^^^^^^^^^^^^^^^^^^^^\n  File \"C:\\Users\\mjeevaba\\AppData\\Local\\Programs\\Python\\Python311\\Lib\\site-packages\\mysql\\connector\\connection_cext.py\", line 619, in cmd_query\n    raise get_mysql_exception(\nmysql.connector.errors.ProgrammingError: 1054 (42S22): Unknown column 'FkGuid' in 'field list'\n", "process": "ddqc"}
{"timestamp": "2023-09-08 15:17:22", "level": "INFO", "module": "test", "function": "<module>", "line": 38, "message": "ddqc-- execution started", "process": "ddqc"}
{"timestamp": "2023-09-08 15:19:13", "level": "ERROR", "module": "test", "function": "<module>", "line": 52, "message": "Traceback (most recent call last):\n  File \"C:\\Users\\mjeevaba\\AppData\\Local\\Programs\\Python\\Python311\\Lib\\site-packages\\mysql\\connector\\connection_cext.py\", line 611, in cmd_query\n    self._cmysql.query(\n_mysql_connector.MySQLInterfaceError: Unknown column 'FkGuid' in 'field list'\n\nThe above exception was the direct cause of the following exception:\n\nTraceback (most recent call last):\n  File \"c:\\Users\\mjeevaba\\Documents\\Python\\DDQC\\DDQC 2.0\\Code\\DDQC Rule Engine\\test.py\", line 50, in <module>\n    dict_transaction = process(config, dict_transaction)\n                       ^^^^^^^^^^^^^^^^^^^^^^^^^^^^^^^^^\n  File \"c:\\Users\\mjeevaba\\Documents\\Python\\DDQC\\DDQC 2.0\\Code\\DDQC Rule Engine\\Project\\z_process.py\", line 18, in process\n    dict_transaction = call_data_filter.ph2_data_filter(config, dict_transaction)\n                       ^^^^^^^^^^^^^^^^^^^^^^^^^^^^^^^^^^^^^^^^^^^^^^^^^^^^^^^^^^\n  File \"c:\\Users\\mjeevaba\\Documents\\Python\\DDQC\\DDQC 2.0\\Code\\DDQC Rule Engine\\Project\\call_data_filter.py\", line 148, in ph2_data_filter\n    insert_foriegn_db(config, df)\n  File \"c:\\Users\\mjeevaba\\Documents\\Python\\DDQC\\DDQC 2.0\\Code\\DDQC Rule Engine\\Project\\insert_to_db.py\", line 172, in insert_foriegn_db\n    cursor.execute(query)\n  File \"C:\\Users\\mjeevaba\\AppData\\Local\\Programs\\Python\\Python311\\Lib\\site-packages\\mysql\\connector\\cursor_cext.py\", line 330, in execute\n    result = self._cnx.cmd_query(\n             ^^^^^^^^^^^^^^^^^^^^\n  File \"C:\\Users\\mjeevaba\\AppData\\Local\\Programs\\Python\\Python311\\Lib\\site-packages\\mysql\\connector\\connection_cext.py\", line 619, in cmd_query\n    raise get_mysql_exception(\nmysql.connector.errors.ProgrammingError: 1054 (42S22): Unknown column 'FkGuid' in 'field list'\n", "process": "ddqc"}
{"timestamp": "2023-09-08 15:20:05", "level": "INFO", "module": "test", "function": "<module>", "line": 38, "message": "ddqc-- execution started", "process": "ddqc"}
{"timestamp": "2023-09-08 15:20:36", "level": "ERROR", "module": "test", "function": "<module>", "line": 52, "message": "Traceback (most recent call last):\n  File \"C:\\Users\\mjeevaba\\AppData\\Local\\Programs\\Python\\Python311\\Lib\\site-packages\\mysql\\connector\\connection_cext.py\", line 611, in cmd_query\n    self._cmysql.query(\n_mysql_connector.MySQLInterfaceError: Unknown column 'FkGuid' in 'field list'\n\nThe above exception was the direct cause of the following exception:\n\nTraceback (most recent call last):\n  File \"c:\\Users\\mjeevaba\\Documents\\Python\\DDQC\\DDQC 2.0\\Code\\DDQC Rule Engine\\test.py\", line 50, in <module>\n    dict_transaction = process(config, dict_transaction)\n                       ^^^^^^^^^^^^^^^^^^^^^^^^^^^^^^^^^\n  File \"c:\\Users\\mjeevaba\\Documents\\Python\\DDQC\\DDQC 2.0\\Code\\DDQC Rule Engine\\Project\\z_process.py\", line 18, in process\n    dict_transaction = call_data_filter.ph2_data_filter(config, dict_transaction)\n                       ^^^^^^^^^^^^^^^^^^^^^^^^^^^^^^^^^^^^^^^^^^^^^^^^^^^^^^^^^^\n  File \"c:\\Users\\mjeevaba\\Documents\\Python\\DDQC\\DDQC 2.0\\Code\\DDQC Rule Engine\\Project\\call_data_filter.py\", line 148, in ph2_data_filter\n    insert_foriegn_db(config, df)\n  File \"c:\\Users\\mjeevaba\\Documents\\Python\\DDQC\\DDQC 2.0\\Code\\DDQC Rule Engine\\Project\\insert_to_db.py\", line 173, in insert_foriegn_db\n    cursor.execute(query)\n  File \"C:\\Users\\mjeevaba\\AppData\\Local\\Programs\\Python\\Python311\\Lib\\site-packages\\mysql\\connector\\cursor_cext.py\", line 330, in execute\n    result = self._cnx.cmd_query(\n             ^^^^^^^^^^^^^^^^^^^^\n  File \"C:\\Users\\mjeevaba\\AppData\\Local\\Programs\\Python\\Python311\\Lib\\site-packages\\mysql\\connector\\connection_cext.py\", line 619, in cmd_query\n    raise get_mysql_exception(\nmysql.connector.errors.ProgrammingError: 1054 (42S22): Unknown column 'FkGuid' in 'field list'\n", "process": "ddqc"}
{"timestamp": "2023-09-08 15:31:42", "level": "INFO", "module": "test", "function": "<module>", "line": 38, "message": "ddqc-- execution started", "process": "ddqc"}
{"timestamp": "2023-09-08 15:32:13", "level": "ERROR", "module": "test", "function": "<module>", "line": 52, "message": "Traceback (most recent call last):\n  File \"C:\\Users\\mjeevaba\\AppData\\Local\\Programs\\Python\\Python311\\Lib\\site-packages\\mysql\\connector\\connection_cext.py\", line 611, in cmd_query\n    self._cmysql.query(\n_mysql_connector.MySQLInterfaceError: Cannot add or update a child row: a foreign key constraint fails (`pronlinedb`.`tbl_ddqc_results_match_py`, CONSTRAINT `fkid2` FOREIGN KEY (`FkGuid`) REFERENCES `tbl_ddqc_wps_py1` (`PkGuid`) ON DELETE NO ACTION ON UPDATE NO ACTION)\n\nThe above exception was the direct cause of the following exception:\n\nTraceback (most recent call last):\n  File \"c:\\Users\\mjeevaba\\Documents\\Python\\DDQC\\DDQC 2.0\\Code\\DDQC Rule Engine\\test.py\", line 50, in <module>\n    dict_transaction = process(config, dict_transaction)\n                       ^^^^^^^^^^^^^^^^^^^^^^^^^^^^^^^^^\n  File \"c:\\Users\\mjeevaba\\Documents\\Python\\DDQC\\DDQC 2.0\\Code\\DDQC Rule Engine\\Project\\z_process.py\", line 18, in process\n    dict_transaction = call_data_filter.ph2_data_filter(config, dict_transaction)\n                       ^^^^^^^^^^^^^^^^^^^^^^^^^^^^^^^^^^^^^^^^^^^^^^^^^^^^^^^^^^\n  File \"c:\\Users\\mjeevaba\\Documents\\Python\\DDQC\\DDQC 2.0\\Code\\DDQC Rule Engine\\Project\\call_data_filter.py\", line 148, in ph2_data_filter\n    insert_foriegn_db(config, df)\n  File \"c:\\Users\\mjeevaba\\Documents\\Python\\DDQC\\DDQC 2.0\\Code\\DDQC Rule Engine\\Project\\insert_to_db.py\", line 173, in insert_foriegn_db\n    cursor.execute(query)\n  File \"C:\\Users\\mjeevaba\\AppData\\Local\\Programs\\Python\\Python311\\Lib\\site-packages\\mysql\\connector\\cursor_cext.py\", line 330, in execute\n    result = self._cnx.cmd_query(\n             ^^^^^^^^^^^^^^^^^^^^\n  File \"C:\\Users\\mjeevaba\\AppData\\Local\\Programs\\Python\\Python311\\Lib\\site-packages\\mysql\\connector\\connection_cext.py\", line 619, in cmd_query\n    raise get_mysql_exception(\nmysql.connector.errors.IntegrityError: 1452 (23000): Cannot add or update a child row: a foreign key constraint fails (`pronlinedb`.`tbl_ddqc_results_match_py`, CONSTRAINT `fkid2` FOREIGN KEY (`FkGuid`) REFERENCES `tbl_ddqc_wps_py1` (`PkGuid`) ON DELETE NO ACTION ON UPDATE NO ACTION)\n", "process": "ddqc"}
{"timestamp": "2023-09-08 15:37:50", "level": "INFO", "module": "test", "function": "<module>", "line": 38, "message": "ddqc-- execution started", "process": "ddqc"}
{"timestamp": "2023-09-08 15:38:06", "level": "INFO", "module": "test", "function": "<module>", "line": 38, "message": "ddqc-- execution started", "process": "ddqc"}
{"timestamp": "2023-09-08 15:43:39", "level": "INFO", "module": "test", "function": "<module>", "line": 38, "message": "ddqc-- execution started", "process": "ddqc"}
{"timestamp": "2023-09-08 15:47:26", "level": "INFO", "module": "test", "function": "<module>", "line": 38, "message": "ddqc-- execution started", "process": "ddqc"}
{"timestamp": "2023-09-08 15:52:33", "level": "INFO", "module": "test", "function": "<module>", "line": 38, "message": "ddqc-- execution started", "process": "ddqc"}
{"timestamp": "2023-09-08 15:52:57", "level": "INFO", "module": "test", "function": "<module>", "line": 38, "message": "ddqc-- execution started", "process": "ddqc"}
{"timestamp": "2023-09-08 15:54:05", "level": "INFO", "module": "test", "function": "<module>", "line": 38, "message": "ddqc-- execution started", "process": "ddqc"}
